2021-12-09 14:07:22,611 INFO    MainThread:37284 [internal.py:wandb_internal():90] W&B internal server running at pid: 37284, started at: 2021-12-09 14:07:22.610200
2021-12-09 14:07:22,613 INFO    WriterThread:37284 [datastore.py:open_for_write():77] open: E:\Pytorch-UNet\wandb\run-20211209_140721-34hy95kb\run-34hy95kb.wandb
2021-12-09 14:07:22,614 DEBUG   HandlerThread:37284 [handler.py:handle_request():130] handle_request: check_version
2021-12-09 14:07:22,615 DEBUG   SenderThread:37284 [sender.py:send():238] send: header
2021-12-09 14:07:22,615 DEBUG   SenderThread:37284 [sender.py:send_request():252] send_request: check_version
2021-12-09 14:07:22,865 DEBUG   SenderThread:37284 [sender.py:send():238] send: run
2021-12-09 14:07:22,870 INFO    SenderThread:37284 [sender.py:_maybe_setup_resume():506] checking resume status for None/U-Net/34hy95kb
2021-12-09 14:07:26,495 ERROR   SenderThread:37284 [retry.py:__call__():126] Retry attempt failed:
Traceback (most recent call last):
  File "C:\Users\2110012.WXCNL-5887\AppData\Roaming\Python\Python36\site-packages\urllib3\connectionpool.py", line 696, in urlopen
    self._prepare_proxy(conn)
  File "C:\Users\2110012.WXCNL-5887\AppData\Roaming\Python\Python36\site-packages\urllib3\connectionpool.py", line 964, in _prepare_proxy
    conn.connect()
  File "C:\Users\2110012.WXCNL-5887\AppData\Roaming\Python\Python36\site-packages\urllib3\connection.py", line 364, in connect
    conn = self._connect_tls_proxy(hostname, conn)
  File "C:\Users\2110012.WXCNL-5887\AppData\Roaming\Python\Python36\site-packages\urllib3\connection.py", line 507, in _connect_tls_proxy
    ssl_context=ssl_context,
  File "C:\Users\2110012.WXCNL-5887\AppData\Roaming\Python\Python36\site-packages\urllib3\util\ssl_.py", line 453, in ssl_wrap_socket
    ssl_sock = _ssl_wrap_socket_impl(sock, context, tls_in_tls)
  File "C:\Users\2110012.WXCNL-5887\AppData\Roaming\Python\Python36\site-packages\urllib3\util\ssl_.py", line 495, in _ssl_wrap_socket_impl
    return ssl_context.wrap_socket(sock)
  File "C:\Users\2110012.WXCNL-5887\anaconda3\envs\Pytorch-UNet\lib\ssl.py", line 407, in wrap_socket
    _context=self, _session=session)
  File "C:\Users\2110012.WXCNL-5887\anaconda3\envs\Pytorch-UNet\lib\ssl.py", line 817, in __init__
    self.do_handshake()
  File "C:\Users\2110012.WXCNL-5887\anaconda3\envs\Pytorch-UNet\lib\ssl.py", line 1077, in do_handshake
    self._sslobj.do_handshake()
  File "C:\Users\2110012.WXCNL-5887\anaconda3\envs\Pytorch-UNet\lib\ssl.py", line 689, in do_handshake
    self._sslobj.do_handshake()
ssl.SSLEOFError: EOF occurred in violation of protocol (_ssl.c:852)

During handling of the above exception, another exception occurred:

Traceback (most recent call last):
  File "C:\Users\2110012.WXCNL-5887\AppData\Roaming\Python\Python36\site-packages\requests\adapters.py", line 449, in send
    timeout=timeout
  File "C:\Users\2110012.WXCNL-5887\AppData\Roaming\Python\Python36\site-packages\urllib3\connectionpool.py", line 756, in urlopen
    method, url, error=e, _pool=self, _stacktrace=sys.exc_info()[2]
  File "C:\Users\2110012.WXCNL-5887\AppData\Roaming\Python\Python36\site-packages\urllib3\util\retry.py", line 574, in increment
    raise MaxRetryError(_pool, url, error or ResponseError(cause))
urllib3.exceptions.MaxRetryError: HTTPSConnectionPool(host='api.wandb.ai', port=443): Max retries exceeded with url: /graphql (Caused by SSLError(SSLEOFError(8, 'EOF occurred in violation of protocol (_ssl.c:852)'),))

During handling of the above exception, another exception occurred:

Traceback (most recent call last):
  File "C:\Users\2110012.WXCNL-5887\anaconda3\envs\Pytorch-UNet\lib\site-packages\wandb\sdk\lib\retry.py", line 102, in __call__
    result = self._call_fn(*args, **kwargs)
  File "C:\Users\2110012.WXCNL-5887\anaconda3\envs\Pytorch-UNet\lib\site-packages\wandb\sdk\internal\internal_api.py", line 141, in execute
    return self.client.execute(*args, **kwargs)
  File "C:\Users\2110012.WXCNL-5887\anaconda3\envs\Pytorch-UNet\lib\site-packages\wandb\vendor\gql-0.2.0\gql\client.py", line 52, in execute
    result = self._get_result(document, *args, **kwargs)
  File "C:\Users\2110012.WXCNL-5887\anaconda3\envs\Pytorch-UNet\lib\site-packages\wandb\vendor\gql-0.2.0\gql\client.py", line 60, in _get_result
    return self.transport.execute(document, *args, **kwargs)
  File "C:\Users\2110012.WXCNL-5887\anaconda3\envs\Pytorch-UNet\lib\site-packages\wandb\vendor\gql-0.2.0\gql\transport\requests.py", line 38, in execute
    request = requests.post(self.url, **post_args)
  File "C:\Users\2110012.WXCNL-5887\AppData\Roaming\Python\Python36\site-packages\requests\api.py", line 117, in post
    return request('post', url, data=data, json=json, **kwargs)
  File "C:\Users\2110012.WXCNL-5887\AppData\Roaming\Python\Python36\site-packages\requests\api.py", line 61, in request
    return session.request(method=method, url=url, **kwargs)
  File "C:\Users\2110012.WXCNL-5887\AppData\Roaming\Python\Python36\site-packages\requests\sessions.py", line 542, in request
    resp = self.send(prep, **send_kwargs)
  File "C:\Users\2110012.WXCNL-5887\AppData\Roaming\Python\Python36\site-packages\requests\sessions.py", line 655, in send
    r = adapter.send(request, **kwargs)
  File "C:\Users\2110012.WXCNL-5887\AppData\Roaming\Python\Python36\site-packages\requests\adapters.py", line 514, in send
    raise SSLError(e, request=request)
requests.exceptions.SSLError: HTTPSConnectionPool(host='api.wandb.ai', port=443): Max retries exceeded with url: /graphql (Caused by SSLError(SSLEOFError(8, 'EOF occurred in violation of protocol (_ssl.c:852)'),))
2021-12-09 14:07:39,627 INFO    SenderThread:37284 [dir_watcher.py:__init__():169] watching files in: E:\Pytorch-UNet\wandb\run-20211209_140721-34hy95kb\files
2021-12-09 14:07:39,627 INFO    SenderThread:37284 [sender.py:_start_run_threads():828] run started: 34hy95kb with start time 1639030041
2021-12-09 14:07:39,627 DEBUG   SenderThread:37284 [sender.py:send():238] send: summary
2021-12-09 14:07:39,627 DEBUG   HandlerThread:37284 [handler.py:handle_request():130] handle_request: run_start
2021-12-09 14:07:39,629 INFO    SenderThread:37284 [sender.py:_save_file():960] saving file wandb-summary.json with policy end
2021-12-09 14:07:40,102 DEBUG   HandlerThread:37284 [meta.py:__init__():40] meta init
2021-12-09 14:07:40,102 DEBUG   HandlerThread:37284 [meta.py:__init__():54] meta init done
2021-12-09 14:07:40,102 DEBUG   HandlerThread:37284 [meta.py:probe():214] probe
2021-12-09 14:07:40,166 DEBUG   HandlerThread:37284 [meta.py:_setup_git():204] setup git
2021-12-09 14:07:40,297 DEBUG   HandlerThread:37284 [meta.py:_setup_git():211] setup git done
2021-12-09 14:07:40,297 DEBUG   HandlerThread:37284 [meta.py:_save_pip():58] save pip
2021-12-09 14:07:40,301 DEBUG   HandlerThread:37284 [meta.py:_save_pip():72] save pip done
2021-12-09 14:07:40,302 DEBUG   HandlerThread:37284 [meta.py:_save_conda():79] save conda
2021-12-09 14:07:40,628 INFO    Thread-12 :37284 [dir_watcher.py:_on_file_created():217] file/dir created: E:\Pytorch-UNet\wandb\run-20211209_140721-34hy95kb\files\conda-environment.yaml
2021-12-09 14:07:40,629 INFO    Thread-12 :37284 [dir_watcher.py:_on_file_created():217] file/dir created: E:\Pytorch-UNet\wandb\run-20211209_140721-34hy95kb\files\requirements.txt
2021-12-09 14:07:40,629 INFO    Thread-12 :37284 [dir_watcher.py:_on_file_created():217] file/dir created: E:\Pytorch-UNet\wandb\run-20211209_140721-34hy95kb\files\wandb-summary.json
2021-12-09 14:07:43,520 WARNING MainThread:37284 [internal.py:wandb_internal():146] Internal process interrupt: 1
2021-12-09 14:07:43,631 INFO    Thread-12 :37284 [dir_watcher.py:_on_file_modified():230] file/dir modified: E:\Pytorch-UNet\wandb\run-20211209_140721-34hy95kb\files\conda-environment.yaml
2021-12-09 14:07:44,208 DEBUG   HandlerThread:37284 [meta.py:_save_conda():89] save conda done
2021-12-09 14:07:44,209 DEBUG   HandlerThread:37284 [meta.py:probe():252] probe done
2021-12-09 14:07:44,213 DEBUG   SenderThread:37284 [sender.py:send():238] send: files
2021-12-09 14:07:44,213 INFO    SenderThread:37284 [sender.py:_save_file():960] saving file wandb-metadata.json with policy now
2021-12-09 14:07:44,632 INFO    Thread-12 :37284 [dir_watcher.py:_on_file_created():217] file/dir created: E:\Pytorch-UNet\wandb\run-20211209_140721-34hy95kb\files\wandb-metadata.json
2021-12-09 14:07:45,198 INFO    Thread-17 :37284 [upload_job.py:push():137] Uploaded file C:\Users\211001~1.WXC\AppData\Local\Temp\tmp4xgr2__8wandb\2d94jlpj-wandb-metadata.json
2021-12-09 14:08:09,102 DEBUG   SenderThread:37284 [sender.py:send():238] send: stats
2021-12-09 14:08:40,365 DEBUG   SenderThread:37284 [sender.py:send():238] send: stats
2021-12-09 14:09:11,663 DEBUG   SenderThread:37284 [sender.py:send():238] send: stats
2021-12-09 14:09:34,734 WARNING MainThread:37284 [internal.py:wandb_internal():146] Internal process interrupt: 2
2021-12-09 14:09:34,734 ERROR   MainThread:37284 [internal.py:wandb_internal():149] Internal process interrupted.
2021-12-09 14:09:35,687 INFO    HandlerThread:37284 [handler.py:finish():731] shutting down handler
2021-12-09 14:09:35,689 INFO    WriterThread:37284 [datastore.py:close():281] close: E:\Pytorch-UNet\wandb\run-20211209_140721-34hy95kb\run-34hy95kb.wandb
2021-12-09 14:09:35,689 INFO    SenderThread:37284 [sender.py:finish():1091] shutting down sender
2021-12-09 14:09:35,689 INFO    SenderThread:37284 [dir_watcher.py:finish():283] shutting down directory watcher
2021-12-09 14:09:35,746 INFO    SenderThread:37284 [dir_watcher.py:finish():313] scan: E:\Pytorch-UNet\wandb\run-20211209_140721-34hy95kb\files
2021-12-09 14:09:35,747 INFO    SenderThread:37284 [dir_watcher.py:finish():327] scan save: E:\Pytorch-UNet\wandb\run-20211209_140721-34hy95kb\files\conda-environment.yaml conda-environment.yaml
2021-12-09 14:09:35,747 INFO    SenderThread:37284 [dir_watcher.py:finish():327] scan save: E:\Pytorch-UNet\wandb\run-20211209_140721-34hy95kb\files\config.yaml config.yaml
2021-12-09 14:09:35,748 INFO    SenderThread:37284 [dir_watcher.py:finish():327] scan save: E:\Pytorch-UNet\wandb\run-20211209_140721-34hy95kb\files\requirements.txt requirements.txt
2021-12-09 14:09:35,755 INFO    SenderThread:37284 [dir_watcher.py:finish():327] scan save: E:\Pytorch-UNet\wandb\run-20211209_140721-34hy95kb\files\wandb-metadata.json wandb-metadata.json
2021-12-09 14:09:35,755 INFO    SenderThread:37284 [dir_watcher.py:finish():327] scan save: E:\Pytorch-UNet\wandb\run-20211209_140721-34hy95kb\files\wandb-summary.json wandb-summary.json
2021-12-09 14:09:35,756 INFO    SenderThread:37284 [file_pusher.py:finish():177] shutting down file pusher
2021-12-09 14:09:35,756 INFO    SenderThread:37284 [file_pusher.py:join():182] waiting for file pusher
2021-12-09 14:09:36,647 INFO    Thread-18 :37284 [upload_job.py:push():137] Uploaded file E:\Pytorch-UNet\wandb\run-20211209_140721-34hy95kb\files\conda-environment.yaml
2021-12-09 14:09:36,660 INFO    Thread-20 :37284 [upload_job.py:push():137] Uploaded file E:\Pytorch-UNet\wandb\run-20211209_140721-34hy95kb\files\requirements.txt
2021-12-09 14:09:36,685 INFO    Thread-19 :37284 [upload_job.py:push():137] Uploaded file E:\Pytorch-UNet\wandb\run-20211209_140721-34hy95kb\files\config.yaml
2021-12-09 14:09:36,887 INFO    Thread-21 :37284 [upload_job.py:push():137] Uploaded file E:\Pytorch-UNet\wandb\run-20211209_140721-34hy95kb\files\wandb-summary.json
2021-12-09 14:09:37,497 INFO    MainThread:37284 [internal.py:handle_exit():77] Internal process exited
