2021-12-09 14:22:31,042 INFO    MainThread:34468 [wandb_setup.py:_flush():71] setting env: {}
2021-12-09 14:22:31,042 INFO    MainThread:34468 [wandb_setup.py:_flush():71] setting login settings: {'anonymous': 'must'}
2021-12-09 14:22:31,042 INFO    MainThread:34468 [wandb_init.py:_log_setup():371] Logging user logs to E:\Pytorch-UNet\wandb\run-20211209_142231-ltg8qblu\logs\debug.log
2021-12-09 14:22:31,042 INFO    MainThread:34468 [wandb_init.py:_log_setup():372] Logging internal logs to E:\Pytorch-UNet\wandb\run-20211209_142231-ltg8qblu\logs\debug-internal.log
2021-12-09 14:22:31,043 INFO    MainThread:34468 [wandb_init.py:init():404] calling init triggers
2021-12-09 14:22:31,043 INFO    MainThread:34468 [wandb_init.py:init():411] wandb.init called with sweep_config: {}
config: {}
2021-12-09 14:22:31,044 INFO    MainThread:34468 [wandb_init.py:init():449] starting backend
2021-12-09 14:22:31,044 INFO    MainThread:34468 [backend.py:_multiprocessing_setup():97] multiprocessing start_methods=spawn, using: spawn
2021-12-09 14:22:31,049 INFO    MainThread:34468 [backend.py:ensure_launched():199] starting backend process...
2021-12-09 14:22:31,139 INFO    MainThread:34468 [backend.py:ensure_launched():205] started backend process with pid: 39520
2021-12-09 14:22:31,139 INFO    MainThread:34468 [wandb_init.py:init():458] backend started and connected
2021-12-09 14:22:31,141 INFO    MainThread:34468 [wandb_init.py:init():519] updated telemetry
2021-12-09 14:22:31,208 INFO    MainThread:34468 [wandb_init.py:init():549] communicating current version
2021-12-09 14:22:32,290 INFO    MainThread:34468 [wandb_init.py:init():554] got version response 
2021-12-09 14:22:32,290 INFO    MainThread:34468 [wandb_init.py:init():564] communicating run to backend with 30 second timeout
2021-12-09 14:23:02,291 INFO    MainThread:34468 [interface_queue.py:_communicate_run():336] couldn't get run from backend
2021-12-09 14:23:02,291 ERROR   MainThread:34468 [wandb_init.py:init():569] backend process timed out
2021-12-09 14:23:02,291 ERROR   MainThread:34468 [wandb_init.py:init():578] encountered error: Error communicating with wandb process
try: wandb.init(settings=wandb.Settings(start_method='fork'))
or:  wandb.init(settings=wandb.Settings(start_method='thread'))
For more info see: https://docs.wandb.ai/library/init#init-start-error
