2022-01-14 17:16:41,890 INFO    MainThread:27228 [internal.py:wandb_internal():90] W&B internal server running at pid: 27228, started at: 2022-01-14 17:16:41.890154
2022-01-14 17:16:41,892 INFO    WriterThread:27228 [datastore.py:open_for_write():77] open: E:\Pytorch-UNet\wandb\run-20220114_171640-2w05amse\run-2w05amse.wandb
2022-01-14 17:16:41,892 DEBUG   HandlerThread:27228 [handler.py:handle_request():130] handle_request: check_version
2022-01-14 17:16:41,894 DEBUG   SenderThread:27228 [sender.py:send():238] send: header
2022-01-14 17:16:41,895 DEBUG   SenderThread:27228 [sender.py:send_request():252] send_request: check_version
2022-01-14 17:16:42,779 DEBUG   SenderThread:27228 [sender.py:send():238] send: run
2022-01-14 17:16:42,781 INFO    SenderThread:27228 [sender.py:_maybe_setup_resume():506] checking resume status for hyan1234/U-Net/2w05amse
2022-01-14 17:16:43,512 ERROR   SenderThread:27228 [internal_api.py:execute():144] 401 response executing GraphQL.
2022-01-14 17:16:43,512 ERROR   SenderThread:27228 [internal_api.py:execute():145] {"errors":[{"message":"permission denied","path":["upsertBucket"],"extensions":{"code":"PERMISSION_ERROR"}}],"data":{"upsertBucket":null}}
2022-01-14 17:16:43,781 INFO    WriterThread:27228 [datastore.py:close():281] close: E:\Pytorch-UNet\wandb\run-20220114_171640-2w05amse\run-2w05amse.wandb
2022-01-14 17:16:43,781 INFO    HandlerThread:27228 [handler.py:finish():731] shutting down handler
2022-01-14 17:16:43,893 ERROR   MainThread:27228 [internal.py:wandb_internal():158] Thread SenderThread:
Traceback (most recent call last):
  File "C:\Users\2110012.WXCNL-5887\anaconda3\envs\Pytorch-UNet\lib\site-packages\wandb\sdk\lib\retry.py", line 102, in __call__
    result = self._call_fn(*args, **kwargs)
  File "C:\Users\2110012.WXCNL-5887\anaconda3\envs\Pytorch-UNet\lib\site-packages\wandb\sdk\internal\internal_api.py", line 147, in execute
    six.reraise(*sys.exc_info())
  File "C:\Users\2110012.WXCNL-5887\anaconda3\envs\Pytorch-UNet\lib\site-packages\six.py", line 719, in reraise
    raise value
  File "C:\Users\2110012.WXCNL-5887\anaconda3\envs\Pytorch-UNet\lib\site-packages\wandb\sdk\internal\internal_api.py", line 141, in execute
    return self.client.execute(*args, **kwargs)
  File "C:\Users\2110012.WXCNL-5887\anaconda3\envs\Pytorch-UNet\lib\site-packages\wandb\vendor\gql-0.2.0\gql\client.py", line 52, in execute
    result = self._get_result(document, *args, **kwargs)
  File "C:\Users\2110012.WXCNL-5887\anaconda3\envs\Pytorch-UNet\lib\site-packages\wandb\vendor\gql-0.2.0\gql\client.py", line 60, in _get_result
    return self.transport.execute(document, *args, **kwargs)
  File "C:\Users\2110012.WXCNL-5887\anaconda3\envs\Pytorch-UNet\lib\site-packages\wandb\vendor\gql-0.2.0\gql\transport\requests.py", line 39, in execute
    request.raise_for_status()
  File "C:\Users\2110012.WXCNL-5887\AppData\Roaming\Python\Python36\site-packages\requests\models.py", line 953, in raise_for_status
    raise HTTPError(http_error_msg, response=self)
requests.exceptions.HTTPError: 401 Client Error: Unauthorized for url: https://api.wandb.ai/graphql

During handling of the above exception, another exception occurred:

Traceback (most recent call last):
  File "C:\Users\2110012.WXCNL-5887\anaconda3\envs\Pytorch-UNet\lib\site-packages\wandb\apis\normalize.py", line 24, in wrapper
    return func(*args, **kwargs)
  File "C:\Users\2110012.WXCNL-5887\anaconda3\envs\Pytorch-UNet\lib\site-packages\wandb\sdk\internal\internal_api.py", line 1298, in upsert_run
    response = self.gql(mutation, variable_values=variable_values, **kwargs)
  File "C:\Users\2110012.WXCNL-5887\anaconda3\envs\Pytorch-UNet\lib\site-packages\wandb\sdk\lib\retry.py", line 118, in __call__
    if not check_retry_fn(e):
  File "C:\Users\2110012.WXCNL-5887\anaconda3\envs\Pytorch-UNet\lib\site-packages\wandb\util.py", line 817, in no_retry_auth
    raise CommError("Invalid or missing api_key.  Run wandb login")
wandb.errors.CommError: Invalid or missing api_key.  Run wandb login

During handling of the above exception, another exception occurred:

Traceback (most recent call last):
  File "C:\Users\2110012.WXCNL-5887\anaconda3\envs\Pytorch-UNet\lib\site-packages\wandb\sdk\internal\internal_util.py", line 52, in run
    self._run()
  File "C:\Users\2110012.WXCNL-5887\anaconda3\envs\Pytorch-UNet\lib\site-packages\wandb\sdk\internal\internal_util.py", line 102, in _run
    self._process(record)
  File "C:\Users\2110012.WXCNL-5887\anaconda3\envs\Pytorch-UNet\lib\site-packages\wandb\sdk\internal\internal.py", line 291, in _process
    self._sm.send(record)
  File "C:\Users\2110012.WXCNL-5887\anaconda3\envs\Pytorch-UNet\lib\site-packages\wandb\sdk\internal\sender.py", line 240, in send
    send_handler(record)
  File "C:\Users\2110012.WXCNL-5887\anaconda3\envs\Pytorch-UNet\lib\site-packages\wandb\sdk\internal\sender.py", line 708, in send_run
    self._init_run(run, config_value_dict)
  File "C:\Users\2110012.WXCNL-5887\anaconda3\envs\Pytorch-UNet\lib\site-packages\wandb\sdk\internal\sender.py", line 746, in _init_run
    commit=run.git.last_commit or None,
  File "C:\Users\2110012.WXCNL-5887\anaconda3\envs\Pytorch-UNet\lib\site-packages\wandb\apis\normalize.py", line 62, in wrapper
    six.reraise(CommError, CommError(message, err), sys.exc_info()[2])
  File "C:\Users\2110012.WXCNL-5887\anaconda3\envs\Pytorch-UNet\lib\site-packages\six.py", line 718, in reraise
    raise value.with_traceback(tb)
  File "C:\Users\2110012.WXCNL-5887\anaconda3\envs\Pytorch-UNet\lib\site-packages\wandb\apis\normalize.py", line 24, in wrapper
    return func(*args, **kwargs)
  File "C:\Users\2110012.WXCNL-5887\anaconda3\envs\Pytorch-UNet\lib\site-packages\wandb\sdk\internal\internal_api.py", line 1298, in upsert_run
    response = self.gql(mutation, variable_values=variable_values, **kwargs)
  File "C:\Users\2110012.WXCNL-5887\anaconda3\envs\Pytorch-UNet\lib\site-packages\wandb\sdk\lib\retry.py", line 118, in __call__
    if not check_retry_fn(e):
  File "C:\Users\2110012.WXCNL-5887\anaconda3\envs\Pytorch-UNet\lib\site-packages\wandb\util.py", line 817, in no_retry_auth
    raise CommError("Invalid or missing api_key.  Run wandb login")
wandb.errors.CommError: Invalid or missing api_key.  Run wandb login
2022-01-14 17:16:45,942 INFO    MainThread:27228 [internal.py:handle_exit():77] Internal process exited
