2022-01-11 09:55:01,492 INFO    MainThread:64760 [internal.py:wandb_internal():90] W&B internal server running at pid: 64760, started at: 2022-01-11 09:55:01.492654
2022-01-11 09:55:01,494 INFO    WriterThread:64760 [datastore.py:open_for_write():77] open: E:\Pytorch-UNet\wandb\run-20220111_095500-1kpubdr8\run-1kpubdr8.wandb
2022-01-11 09:55:01,494 DEBUG   HandlerThread:64760 [handler.py:handle_request():130] handle_request: check_version
2022-01-11 09:55:01,496 DEBUG   SenderThread:64760 [sender.py:send():238] send: header
2022-01-11 09:55:01,496 DEBUG   SenderThread:64760 [sender.py:send_request():252] send_request: check_version
2022-01-11 09:55:01,758 DEBUG   SenderThread:64760 [sender.py:send():238] send: run
2022-01-11 09:55:01,760 INFO    SenderThread:64760 [sender.py:_maybe_setup_resume():506] checking resume status for None/U-Net/1kpubdr8
2022-01-11 09:55:05,110 ERROR   SenderThread:64760 [retry.py:__call__():126] Retry attempt failed:
Traceback (most recent call last):
  File "C:\Users\2110012.WXCNL-5887\AppData\Roaming\Python\Python36\site-packages\urllib3\connectionpool.py", line 696, in urlopen
    self._prepare_proxy(conn)
  File "C:\Users\2110012.WXCNL-5887\AppData\Roaming\Python\Python36\site-packages\urllib3\connectionpool.py", line 964, in _prepare_proxy
    conn.connect()
  File "C:\Users\2110012.WXCNL-5887\AppData\Roaming\Python\Python36\site-packages\urllib3\connection.py", line 364, in connect
    conn = self._connect_tls_proxy(hostname, conn)
  File "C:\Users\2110012.WXCNL-5887\AppData\Roaming\Python\Python36\site-packages\urllib3\connection.py", line 507, in _connect_tls_proxy
    ssl_context=ssl_context,
  File "C:\Users\2110012.WXCNL-5887\AppData\Roaming\Python\Python36\site-packages\urllib3\util\ssl_.py", line 453, in ssl_wrap_socket
    ssl_sock = _ssl_wrap_socket_impl(sock, context, tls_in_tls)
  File "C:\Users\2110012.WXCNL-5887\AppData\Roaming\Python\Python36\site-packages\urllib3\util\ssl_.py", line 495, in _ssl_wrap_socket_impl
    return ssl_context.wrap_socket(sock)
  File "C:\Users\2110012.WXCNL-5887\anaconda3\envs\Pytorch-UNet\lib\ssl.py", line 407, in wrap_socket
    _context=self, _session=session)
  File "C:\Users\2110012.WXCNL-5887\anaconda3\envs\Pytorch-UNet\lib\ssl.py", line 817, in __init__
    self.do_handshake()
  File "C:\Users\2110012.WXCNL-5887\anaconda3\envs\Pytorch-UNet\lib\ssl.py", line 1077, in do_handshake
    self._sslobj.do_handshake()
  File "C:\Users\2110012.WXCNL-5887\anaconda3\envs\Pytorch-UNet\lib\ssl.py", line 689, in do_handshake
    self._sslobj.do_handshake()
ssl.SSLEOFError: EOF occurred in violation of protocol (_ssl.c:852)

During handling of the above exception, another exception occurred:

Traceback (most recent call last):
  File "C:\Users\2110012.WXCNL-5887\AppData\Roaming\Python\Python36\site-packages\requests\adapters.py", line 449, in send
    timeout=timeout
  File "C:\Users\2110012.WXCNL-5887\AppData\Roaming\Python\Python36\site-packages\urllib3\connectionpool.py", line 756, in urlopen
    method, url, error=e, _pool=self, _stacktrace=sys.exc_info()[2]
  File "C:\Users\2110012.WXCNL-5887\AppData\Roaming\Python\Python36\site-packages\urllib3\util\retry.py", line 574, in increment
    raise MaxRetryError(_pool, url, error or ResponseError(cause))
urllib3.exceptions.MaxRetryError: HTTPSConnectionPool(host='api.wandb.ai', port=443): Max retries exceeded with url: /graphql (Caused by SSLError(SSLEOFError(8, 'EOF occurred in violation of protocol (_ssl.c:852)'),))

During handling of the above exception, another exception occurred:

Traceback (most recent call last):
  File "C:\Users\2110012.WXCNL-5887\anaconda3\envs\Pytorch-UNet\lib\site-packages\wandb\sdk\lib\retry.py", line 102, in __call__
    result = self._call_fn(*args, **kwargs)
  File "C:\Users\2110012.WXCNL-5887\anaconda3\envs\Pytorch-UNet\lib\site-packages\wandb\sdk\internal\internal_api.py", line 141, in execute
    return self.client.execute(*args, **kwargs)
  File "C:\Users\2110012.WXCNL-5887\anaconda3\envs\Pytorch-UNet\lib\site-packages\wandb\vendor\gql-0.2.0\gql\client.py", line 52, in execute
    result = self._get_result(document, *args, **kwargs)
  File "C:\Users\2110012.WXCNL-5887\anaconda3\envs\Pytorch-UNet\lib\site-packages\wandb\vendor\gql-0.2.0\gql\client.py", line 60, in _get_result
    return self.transport.execute(document, *args, **kwargs)
  File "C:\Users\2110012.WXCNL-5887\anaconda3\envs\Pytorch-UNet\lib\site-packages\wandb\vendor\gql-0.2.0\gql\transport\requests.py", line 38, in execute
    request = requests.post(self.url, **post_args)
  File "C:\Users\2110012.WXCNL-5887\AppData\Roaming\Python\Python36\site-packages\requests\api.py", line 117, in post
    return request('post', url, data=data, json=json, **kwargs)
  File "C:\Users\2110012.WXCNL-5887\AppData\Roaming\Python\Python36\site-packages\requests\api.py", line 61, in request
    return session.request(method=method, url=url, **kwargs)
  File "C:\Users\2110012.WXCNL-5887\AppData\Roaming\Python\Python36\site-packages\requests\sessions.py", line 542, in request
    resp = self.send(prep, **send_kwargs)
  File "C:\Users\2110012.WXCNL-5887\AppData\Roaming\Python\Python36\site-packages\requests\sessions.py", line 655, in send
    r = adapter.send(request, **kwargs)
  File "C:\Users\2110012.WXCNL-5887\AppData\Roaming\Python\Python36\site-packages\requests\adapters.py", line 514, in send
    raise SSLError(e, request=request)
requests.exceptions.SSLError: HTTPSConnectionPool(host='api.wandb.ai', port=443): Max retries exceeded with url: /graphql (Caused by SSLError(SSLEOFError(8, 'EOF occurred in violation of protocol (_ssl.c:852)'),))
2022-01-11 09:55:31,758 DEBUG   HandlerThread:64760 [handler.py:handle_request():130] handle_request: shutdown
2022-01-11 09:55:31,759 INFO    HandlerThread:64760 [handler.py:finish():731] shutting down handler
2022-01-11 09:55:31,788 INFO    WriterThread:64760 [datastore.py:close():281] close: E:\Pytorch-UNet\wandb\run-20220111_095500-1kpubdr8\run-1kpubdr8.wandb
2022-01-11 09:57:30,666 INFO    SenderThread:64760 [dir_watcher.py:__init__():169] watching files in: E:\Pytorch-UNet\wandb\run-20220111_095500-1kpubdr8\files
2022-01-11 09:57:30,666 INFO    SenderThread:64760 [sender.py:_start_run_threads():828] run started: 1kpubdr8 with start time 1641866100
2022-01-11 09:57:30,666 INFO    SenderThread:64760 [sender.py:finish():1091] shutting down sender
2022-01-11 09:57:30,666 INFO    SenderThread:64760 [dir_watcher.py:finish():283] shutting down directory watcher
2022-01-11 09:57:31,667 INFO    SenderThread:64760 [dir_watcher.py:finish():313] scan: E:\Pytorch-UNet\wandb\run-20220111_095500-1kpubdr8\files
2022-01-11 09:57:31,668 INFO    SenderThread:64760 [dir_watcher.py:finish():327] scan save: E:\Pytorch-UNet\wandb\run-20220111_095500-1kpubdr8\files\config.yaml config.yaml
2022-01-11 09:57:31,668 INFO    SenderThread:64760 [file_pusher.py:finish():177] shutting down file pusher
2022-01-11 09:57:31,668 INFO    SenderThread:64760 [file_pusher.py:join():182] waiting for file pusher
2022-01-11 09:57:32,785 INFO    Thread-14 :64760 [upload_job.py:push():137] Uploaded file E:\Pytorch-UNet\wandb\run-20220111_095500-1kpubdr8\files\config.yaml
2022-01-11 09:57:33,546 INFO    MainThread:64760 [internal.py:handle_exit():77] Internal process exited
