INFO: Starting training:
        Epochs:          5
        Batch size:      1
        Learning rate:   1e-05
        Training size:   1530
        Validation size: 170
        Checkpoints:     True
        Device:          cuda
        Images scaling:  0.5
        Mixed Precision: False

Epoch 1/5:   0%|          | 0/1530 [08:14<?, ?img/s]
Traceback (most recent call last):
  File "E:/Pytorch-UNet/train.py", line 191, in <module>
    amp=args.amp)
  File "E:/Pytorch-UNet/train.py", line 93, in train_net
    loss = criterion(masks_pred, true_masks) \
  File "_pydevd_bundle\pydevd_cython_win32_36_64.pyx", line 1180, in _pydevd_bundle.pydevd_cython_win32_36_64.SafeCallWrapper.__call__
  File "_pydevd_bundle\pydevd_cython_win32_36_64.pyx", line 621, in _pydevd_bundle.pydevd_cython_win32_36_64.PyDBFrame.trace_dispatch
  File "_pydevd_bundle\pydevd_cython_win32_36_64.pyx", line 1096, in _pydevd_bundle.pydevd_cython_win32_36_64.PyDBFrame.trace_dispatch
  File "_pydevd_bundle\pydevd_cython_win32_36_64.pyx", line 1089, in _pydevd_bundle.pydevd_cython_win32_36_64.PyDBFrame.trace_dispatch
  File "_pydevd_bundle\pydevd_cython_win32_36_64.pyx", line 318, in _pydevd_bundle.pydevd_cython_win32_36_64.PyDBFrame.do_wait_suspend
  File "C:\Users\2110012.WXCNL-5887\AppData\Local\JetBrains\Toolbox\apps\PyCharm-P\ch-0\213.6461.77\plugins\python\helpers\pydev\pydevd.py", line 1147, in do_wait_suspend
    self._do_wait_suspend(thread, frame, event, arg, suspend_type, from_this_thread)
  File "C:\Users\2110012.WXCNL-5887\AppData\Local\JetBrains\Toolbox\apps\PyCharm-P\ch-0\213.6461.77\plugins\python\helpers\pydev\pydevd.py", line 1162, in _do_wait_suspend
    time.sleep(0.01)
KeyboardInterrupt
During handling of the above exception, another exception occurred:
Traceback (most recent call last):
  File "C:\Users\2110012.WXCNL-5887\AppData\Local\JetBrains\Toolbox\apps\PyCharm-P\ch-0\213.6461.77\plugins\python\helpers\pydev\pydevd.py", line 2173, in <module>
    main()
  File "C:\Users\2110012.WXCNL-5887\AppData\Local\JetBrains\Toolbox\apps\PyCharm-P\ch-0\213.6461.77\plugins\python\helpers\pydev\pydevd.py", line 2164, in main
    globals = debugger.run(setup['file'], None, None, is_module)
  File "C:\Users\2110012.WXCNL-5887\AppData\Local\JetBrains\Toolbox\apps\PyCharm-P\ch-0\213.6461.77\plugins\python\helpers\pydev\pydevd.py", line 1476, in run
    return self._exec(is_module, entry_point_fn, module_name, file, globals, locals)
  File "C:\Users\2110012.WXCNL-5887\AppData\Local\JetBrains\Toolbox\apps\PyCharm-P\ch-0\213.6461.77\plugins\python\helpers\pydev\pydevd.py", line 1483, in _exec
    pydev_imports.execfile(file, globals, locals)  # execute the script
  File "C:\Users\2110012.WXCNL-5887\AppData\Local\JetBrains\Toolbox\apps\PyCharm-P\ch-0\213.6461.77\plugins\python\helpers\pydev\_pydev_imps\_pydev_execfile.py", line 18, in execfile
    exec(compile(contents+"\n", file, 'exec'), glob, loc)
  File "E:/Pytorch-UNet/train.py", line 191, in <module>
    amp=args.amp)
  File "C:\Users\2110012.WXCNL-5887\anaconda3\envs\Pytorch-UNet\lib\site-packages\torch\serialization.py", line 379, in save
    _save(obj, opened_zipfile, pickle_module, pickle_protocol)
  File "C:\Users\2110012.WXCNL-5887\anaconda3\envs\Pytorch-UNet\lib\site-packages\torch\serialization.py", line 496, in _save
    storage = storage.cpu()
  File "C:\Users\2110012.WXCNL-5887\anaconda3\envs\Pytorch-UNet\lib\site-packages\torch\storage.py", line 72, in cpu
    return self.type(getattr(torch, self.__class__.__name__))
  File "C:\Users\2110012.WXCNL-5887\anaconda3\envs\Pytorch-UNet\lib\site-packages\torch\cuda\__init__.py", line 618, in type
    return super(_CudaBase, self).type(*args, **kwargs)  # type: ignore[misc]
  File "C:\Users\2110012.WXCNL-5887\anaconda3\envs\Pytorch-UNet\lib\site-packages\torch\_utils.py", line 45, in _type
    return dtype(self.size()).copy_(self, non_blocking)
RuntimeError: CUDA error: device-side assert triggered
CUDA kernel errors might be asynchronously reported at some other API call,so the stacktrace below might be incorrect.
